<?xml version="1.0" encoding="UTF-8"?>
<testng-results ignored="0" total="2" passed="1" failed="1" skipped="0">
  <reporter-output>
  </reporter-output>
  <suite started-at="2023-10-06T20:23:59 BST" name="Default suite" finished-at="2023-10-06T20:23:59 BST" duration-ms="98">
    <groups>
    </groups>
    <test started-at="2023-10-06T20:23:59 BST" name="Default test" finished-at="2023-10-06T20:23:59 BST" duration-ms="98">
      <class name="generic.TC_App_Test">
        <test-method signature="testLogin1()[pri:0, instance:generic.TC_App_Test@353d0772]" started-at="2023-10-06T20:23:59 BST" name="testLogin1" finished-at="2023-10-06T20:23:59 BST" duration-ms="21" status="PASS">
          <reporter-output>
          </reporter-output>
        </test-method> <!-- testLogin1 -->
        <test-method signature="testLogin2()[pri:0, instance:generic.TC_App_Test@353d0772]" started-at="2023-10-06T20:23:59 BST" name="testLogin2" finished-at="2023-10-06T20:23:59 BST" duration-ms="19" status="FAIL">
          <exception class="java.lang.AssertionError">
            <message>
              <![CDATA[expected [0] but found [1]]]>
            </message>
            <full-stacktrace>
              <![CDATA[java.lang.AssertionError: expected [0] but found [1]
at org.testng.Assert.fail(Assert.java:99)
at org.testng.Assert.failNotEquals(Assert.java:1037)
at org.testng.Assert.assertEqualsImpl(Assert.java:140)
at org.testng.Assert.assertEquals(Assert.java:122)
at org.testng.Assert.assertEquals(Assert.java:907)
at org.testng.Assert.assertEquals(Assert.java:917)
at generic.TC_App_Test.testLogin2(TC_App_Test.java:20)
at java.base/jdk.internal.reflect.DirectMethodHandleAccessor.invoke(DirectMethodHandleAccessor.java:104)
at java.base/java.lang.reflect.Method.invoke(Method.java:578)
at org.testng.internal.MethodInvocationHelper.invokeMethod(MethodInvocationHelper.java:132)
at org.testng.internal.TestInvoker.invokeMethod(TestInvoker.java:599)
at org.testng.internal.TestInvoker.invokeTestMethod(TestInvoker.java:174)
at org.testng.internal.MethodRunner.runInSequence(MethodRunner.java:46)
at org.testng.internal.TestInvoker$MethodInvocationAgent.invoke(TestInvoker.java:822)
at org.testng.internal.TestInvoker.invokeTestMethods(TestInvoker.java:147)
at org.testng.internal.TestMethodWorker.invokeTestMethods(TestMethodWorker.java:146)
at org.testng.internal.TestMethodWorker.run(TestMethodWorker.java:128)
at java.base/java.util.ArrayList.forEach(ArrayList.java:1511)
at org.testng.TestRunner.privateRun(TestRunner.java:764)
at org.testng.TestRunner.run(TestRunner.java:585)
at org.testng.SuiteRunner.runTest(SuiteRunner.java:384)
at org.testng.SuiteRunner.runSequentially(SuiteRunner.java:378)
at org.testng.SuiteRunner.privateRun(SuiteRunner.java:337)
at org.testng.SuiteRunner.run(SuiteRunner.java:286)
at org.testng.SuiteRunnerWorker.runSuite(SuiteRunnerWorker.java:53)
at org.testng.SuiteRunnerWorker.run(SuiteRunnerWorker.java:96)
at org.testng.TestNG.runSuitesSequentially(TestNG.java:1218)
at org.testng.TestNG.runSuitesLocally(TestNG.java:1140)
at org.testng.TestNG.runSuites(TestNG.java:1069)
at org.testng.TestNG.run(TestNG.java:1037)
at org.testng.remote.AbstractRemoteTestNG.run(AbstractRemoteTestNG.java:115)
at org.testng.remote.RemoteTestNG.initAndRun(RemoteTestNG.java:251)
at org.testng.remote.RemoteTestNG.main(RemoteTestNG.java:77)
]]>
            </full-stacktrace>
          </exception> <!-- java.lang.AssertionError -->
          <reporter-output>
          </reporter-output>
        </test-method> <!-- testLogin2 -->
      </class> <!-- generic.TC_App_Test -->
    </test> <!-- Default test -->
  </suite> <!-- Default suite -->
</testng-results>
